Workbook

Sheet Cover
A1: Annapurna Capital Technologies Pvt. Ltd.
A2: Series B Financial Model — Assignment Workbook
A4: How to use this workbook
A5: • The Assumptions tab is fully filled in with every given fact from the case — historical actuals (FY24–FY26), management's forward guidance (FY27E–FY31E), operational KPIs, unit economics, market sizing, funding history, and the current cap table.
A6: • Every other tab is blank, formatted, and labeled to match the case exactly — column headers, row labels, number formats, and yellow-filled cells are already in place. You build the numbers and formulas.
A7: • Reference the Assumptions tab from formulas in other tabs rather than retyping a number (e.g. =Assumptions!E12) — if a driver changes, you want it to flow through everywhere automatically.
A8: • All figures are in ₹ Lakhs (L) unless a row label says ₹ Crore (Cr). 1 Cr = 100 L.
A9: • FY24–FY26 are given actuals. FY27E–FY31E are the forecast years you are building.
A12: Tabs in this workbook
A13: Assumptions — Every input from the case, filled in.
A14: Revenue Build — Task 1 — build the four-line revenue forecast.
A15: Income Statement — Task 2 — full P&L, FY24 actual through FY31E.
... A20: TAM SAM SOM — Task 4 — your independent market-sizing rebuild.

Sheet Assumptions
A1: ASSUMPTIONS — every given fact from the case
A2: ₹ in Lakhs unless noted | B2: FY24 | C2: FY25 | D2: FY26 | E2: FY27E | F2: FY28E | G2: FY29E | H2: FY30E | I2: FY31E
A4: HISTORICAL INCOME STATEMENT (₹ L) — FY24-FY26 actual
A5: Financing Facilitation Commission | B5: 380 | C5: 1050 | D5: 2460
A6: Warehouse SaaS/IoT Subscription Fee | B6: 100 | C6: 230 | D6: 460
A7: Marketplace Transaction Fee | B7: 60 | C7: 270 | D7: 900
A8: Storage Fee Revenue | B8: 0 | C8: 45 | D8: 640
A9: Total Revenue | B9: 540 | C9: 1595 | D9: 4460
A10: Cost of Revenue | B10: -195 | C10: -545 | D10: -1388
A11: Gross Profit | B11: 345 | C11: 1050 | D11: 3072
A12: Gross Margin % | B12: 0.639 | C12: 0.658 | D12: 0.689
A13: Warehouse Ops & Field Team | B13: -320 | C13: -690 | D13: -1320
A14: Sales & Marketing | B14: -150 | C14: -360 | D14: -640
A15: Technology & Product (R&D) | B15: -240 | C15: -450 | D15: -760
A16: General & Administrative | B16: -130 | C16: -250 | D16: -430
... A22: Net Income (Loss) | B22: -533 | C22: -890 | D22: -568
A24: HISTORICAL BALANCE SHEET (₹ L, year-end) — FY24-FY26 actual
A25: Cash & Equivalents | B25: 675 | C25: 3050 | D25: 1367
A26: Accounts Receivable | B26: 60 | C26: 190 | D26: 460
A27: Prepaid Expenses / Inventory | B27: 80 | C27: 200 | D27: 300
A28: Total Current Assets | B28: 815 | C28: 3440 | D28: 2127
A29: PP&E & Warehouse Structures (net) | B29: 150 | C29: 1515 | D29: 2955
A30: Total Assets | B30: 965 | C30: 4955 | D30: 5082
A31: Accounts Payable | B31: 70 | C31: 180 | D31: 320
A32: Accrued Payroll | B32: 40 | C32: 110 | D32: 185
A33: Short-term Working Capital Loan | B33: 120 | C33: 620 | D33: 1100
A34: Total Liabilities | B34: 230 | C34: 910 | D34: 1605
A35: Paid-in Capital | B35: 1150 | C35: 5350 | D35: 5350
A36: Accumulated Deficit | B36: -415 | C36: -1305 | D36: -1873
A37: Total Equity | B37: 735 | C37: 4045 | D37: 3477
A39: HISTORICAL CASH FLOW STATEMENT (₹ L) — FY24-FY26 actual
A40: Net Income | B40: -533 | C40: -890 | D40: -568
A41: D&A add-back | B41: 30 | C41: 135 | D41: 360
A42: Change in Net Working Capital | B42: -17 | C42: -70 | D42: -155
A43: Cash Flow from Operations | B43: -520 | C43: -825 | D43: -363
A44: Capex | B44: -110 | C44: -1500 | D44: -1800
A45: Cash Flow from Investing | B45: -110 | C45: -1500 | D45: -1800
A46: Equity Raised | B46: 0 | C46: 4200 | D46: 0
A47: Debt Drawn (net) | B47: 105 | C47: 500 | D47: 480
A48: Cash Flow from Financing | B48: 105 | C48: 4700 | D48: 480
...

Sheet Revenue Build
A1: REVENUE BUILD
A2: ₹ in Lakhs unless noted | B2: FY27E | C2: FY28E | D2: FY29E | E2: FY30E | F2: FY31E
A4: 1. FINANCING FACILITATION COMMISSION
A5: Annual Loan Disbursement Volume (₹ Cr) | B5: =Assumptions!E74 -> 436 | C5: =Assumptions!F74 -> 698 | D5: =Assumptions!G74 -> 1047 | E5: =Assumptions!H74 -> 1466 | F5: =Assumptions!I74 -> 1979
A6: Blended Take Rate | B6: =Assumptions!E75 -> 0.065 | C6: =Assumptions!F75 -> 0.067 | D6: =Assumptions!G75 -> 0.069 | E6: =Assumptions!H75 -> 0.07 | F6: =Assumptions!I75 -> 0.071
A7: Financing Facilitation Commission (₹ L) | B7: =B5*B6*100 -> 2834 | C7: =C5*C6*100 -> 4676.6 | D7: =D5*D6*100 -> 7224.3 | E7: =E5*E6*100 -> 10262 | F7: =F5*F6*100 -> 14050.9
A9: 2. WAREHOUSE SAAS/IoT SUBSCRIPTION FEE
A10: Partner Warehouses (cumulative) | B10: =Assumptions!E76 -> 280 | C10: =Assumptions!F76 -> 400 | D10: =Assumptions!G76 -> 520 | E10: =Assumptions!H76 -> 620 | F10: =Assumptions!I76 -> 700
A11: SaaS Fee per Partner Warehouse (₹ L/yr) | B11: =Assumptions!E77 -> 2.5 | C11: =Assumptions!F77 -> 2.6 | D11: =Assumptions!G77 -> 2.7 | E11: =Assumptions!H77 -> 2.8 | F11: =Assumptions!I77 -> 2.9
A12: Warehouse SaaS/IoT Subscription Fee (₹ L) | B12: =B10*B11 -> 700 | C12: =C10*C11 -> 1040 | D12: =D10*D11 -> 1404 | E12: =E10*E11 -> 1736 | F12: =F10*F11 -> 2030
A14: 3. MARKETPLACE TRANSACTION FEE
A15: Marketplace GMV (₹ Cr) | B15: =Assumptions!E74*Assumptions!E78 -> 405.48 | C15: =Assumptions!F74*Assumptions!F78 -> 649.14 | D15: =Assumptions!G74*Assumptions!G78 -> 973.71 | E15: =Assumptions!H74*Assumptions!H78 -> 1363.38 | F15: =Assumptions!I74*Assumptions!I78 -> 1840.47
A16: Marketplace Transaction Fee Rate | B16: =Assumptions!E79 -> 0.04 | C16: =Assumptions!F79 -> 0.041 | D16: =Assumptions!G79 -> 0.042 | E16: =Assumptions!H79 -> 0.043 | F16: =Assumptions!I79 -> 0.044
A17: Marketplace Transaction Fee (₹ L) | B17: =B15*B16*100 -> 1621.92 | C17: =C15*C16*100 -> 2661.474 | D17: =D15*D16*100 -> 4089.582 | E17: =E15*E16*100 -> 5862.534 | F17: =F15*F16*100 -> 8098.068
A19: 4. STORAGE FEE
A20: Owned Mini-Warehouses (cumulative) | B20: =Assumptions!E80 -> 70 | C20: =Assumptions!F80 -> 110 | D20: =Assumptions!G80 -> 160 | E20: =Assumptions!H80 -> 220 | F20: =Assumptions!I80 -> 290
A21: Avg. Storage Revenue per Warehouse (₹ L/yr) | B21: =Assumptions!E81 -> 17 | C21: =Assumptions!F81 -> 19 | D21: =Assumptions!G81 -> 21 | E21: =Assumptions!H81 -> 23 | F21: =Assumptions!I81 -> 25
A22: Storage Fee Revenue (₹ L) | B22: =B20*B21 -> 1190 | C22: =C20*C21 -> 2090 | D22: =D20*D21 -> 3360 | E22: =E20*E21 -> 5060 | F22: =F20*F21 -> 7250
A24: TOTAL REVENUE
A25: Financing Facilitation Commission | B25: =B7 -> 2834 | C25: =C7 -> 4676.6 | D25: =D7 -> 7224.3 | E25: =E7 -> 10262 | F25: =F7 -> 14050.9
A26: Warehouse SaaS/IoT Subscription Fee | B26: =B12 -> 700 | C26: =C12 -> 1040 | D26: =D12 -> 1404 | E26: =E12 -> 1736 | F26: =F12 -> 2030
A27: Marketplace Transaction Fee | B27: =B17 -> 1621.92 | C27: =C17 -> 2661.474 | D27: =D17 -> 4089.582 | E27: =E17 -> 5862.534 | F27: =F17 -> 8098.068
A28: Storage Fee Revenue | B28: =B22 -> 1190 | C28: =C22 -> 2090 | D28: =D22 -> 3360 | E28: =E22 -> 5060 | F28: =F22 -> 7250
A29: TOTAL REVENUE | B29: =SUM(B25:B28) -> 6345.92 | C29: =SUM(C25:C28) -> 10468.074 | D29: =SUM(D25:D28) -> 16077.882 | E29: =SUM(E25:E28) -> 22920.534 | F29: =SUM(F25:F28) -> 31428.968

Sheet Income Statement
A1: INCOME STATEMENT —(₹ Lakhs)
A2: ₹ in Lakhs unless noted | B2: FY27E | C2: FY28E | D2: FY29E | E2: FY30E | F2: FY31E
A4: Financing Facilitation Commission | B4: ='Revenue Build'!B25 -> 2834 | C4: ='Revenue Build'!C25 -> 4676.6 | D4: ='Revenue Build'!D25 -> 7224.3 | E4: ='Revenue Build'!E25 -> 10262 | F4: ='Revenue Build'!F25 -> 14050.9
A5: Warehouse SaaS/IoT Subscription Fee | B5: ='Revenue Build'!B26 -> 700 | C5: ='Revenue Build'!C26 -> 1040 | D5: ='Revenue Build'!D26 -> 1404 | E5: ='Revenue Build'!E26 -> 1736 | F5: ='Revenue Build'!F26 -> 2030
A6: Marketplace Transaction Fee | B6: ='Revenue Build'!B27 -> 1621.92 | C6: ='Revenue Build'!C27 -> 2661.474 | D6: ='Revenue Build'!D27 -> 4089.582 | E6: ='Revenue Build'!E27 -> 5862.534 | F6: ='Revenue Build'!F27 -> 8098.068
A7: Storage Fee Revenue | B7: ='Revenue Build'!B28 -> 1190 | C7: ='Revenue Build'!C28 -> 2090 | D7: ='Revenue Build'!D28 -> 3360 | E7: ='Revenue Build'!E28 -> 5060 | F7: ='Revenue Build'!F28 -> 7250
A8: TOTAL REVENUE | B8: =SUM(B4:B7) -> 6345.92 | C8: =SUM(C4:C7) -> 10468.074 | D8: =SUM(D4:D7) -> 16077.882 | E8: =SUM(E4:E7) -> 22920.534 | F8: =SUM(F4:F7) -> 31428.968
A9: Cost of Revenue | B9: =B8-B10 -> 1903.776 | C9: =C8-C10 -> 3035.7415 | D9: =D8-D10 -> 4501.807 | E9: =E8-E10 -> 6188.5442 | F9: =F8-F10 -> 8171.5317
A10: GROSS PROFIT | B10: =B8*Assumptions!E82 -> 4442.144 | C10: =C8*Assumptions!F82 -> 7432.3325 | D10: =D8*Assumptions!G82 -> 11576.075 | E10: =E8*Assumptions!H82 -> 16731.99 | F10: =F8*Assumptions!I82 -> 23257.436
A11: Gross Margin % | B11: =B10/B8 -> 0.7 | C11: =C10/C8 -> 0.71 | D11: =D10/D8 -> 0.72 | E11: =E10/E8 -> 0.73 | F11: =F10/F8 -> 0.74
A12: Warehouse Ops & Field Team | B12: =B$8*Assumptions!E83 -> 1713.3984 | C12: =C$8*Assumptions!F83 -> 2407.657 | D12: =D$8*Assumptions!G83 -> 3215.5764 | E12: =E$8*Assumptions!H83 -> 4125.6961 | F12: =F$8*Assumptions!I83 -> 5028.6349
A13: Sales & Marketing | B13: =B$8*Assumptions!E84 -> 888.4288 | C13: =C$8*Assumptions!F84 -> 1256.1689 | D13: =D$8*Assumptions!G84 -> 1607.7882 | E13: =E$8*Assumptions!H84 -> 2062.8481 | F13: =F$8*Assumptions!I84 -> 2514.3174
A14: Technology & Product (R&D) | B14: =B$8*Assumptions!E85 -> 1015.3472 | C14: =C$8*Assumptions!F85 -> 1465.5304 | D14: =D$8*Assumptions!G85 -> 1929.3458 | E14: =E$8*Assumptions!H85 -> 2521.2587 | F14: =F$8*Assumptions!I85 -> 3142.8968
A15: General & Administrative | B15: =B$8*Assumptions!E86 -> 571.1328 | C15: =C$8*Assumptions!F86 -> 837.44592 | D15: =D$8*Assumptions!G86 -> 1125.4517 | E15: =E$8*Assumptions!H86 -> 1489.8347 | F15: =F$8*Assumptions!I86 -> 1885.7381
A16: TOTAL OPEX | B16: =SUM(B12:B15) -> 4188.3072 | C16: =SUM(C12:C15) -> 5966.8022 | D16: =SUM(D12:D15) -> 7878.1622 | E16: =SUM(E12:E15) -> 10199.638 | F16: =SUM(F12:F15) -> 12571.587
A17: EBITDA | B17: =B10-B16 -> 253.8368 | C17: =C10-C16 -> 1465.5304 | D17: =D10-D16 -> 3697.9129 | E17: =E10-E16 -> 6532.3522 | F17: =F10-F16 -> 10685.849
A18: EBITDA Margin % | B18: =B17/B8 -> 0.04 | C18: =C17/C8 -> 0.14 | D18: =D17/D8 -> 0.23 | E18: =E17/E8 -> 0.285 | F18: =F17/F8 -> 0.34
A19: Depreciation & Amortization | B19: ='Depreciation Schedule'!B8 -> 525.5 | C19: ='Depreciation Schedule'!C8 -> 772.95 | D19: ='Depreciation Schedule'!D8 -> 1065.655 | E19: ='Depreciation Schedule'!E8 -> 1399.0895 | F19: ='Depreciation Schedule'!F8 -> 1769.1806
A20: EBIT | B20: =B17-B19 -> -271.6632 | C20: =C17-C19 -> 692.58036 | D20: =D17-D19 -> 2632.2579 | E20: =E17-E19 -> 5133.2627 | F20: =F17-F19 -> 8916.6686
A21: Interest Expense | B21: ='Loan Schedule'!B9 -> 180 | C21: ='Loan Schedule'!C9 -> 210 | D21: ='Loan Schedule'!D9 -> 240 | E21: ='Loan Schedule'!E9 -> 270 | F21: ='Loan Schedule'!F9 -> 300
A22: PBT | B22: =B20-B21 -> -451.6632 | C22: =C20-C21 -> 482.58036 | D22: =D20-D21 -> 2392.2579 | E22: =E20-E21 -> 4863.2627 | F22: =F20-F21 -> 8616.6686
A23: Tax | B23: =IF(B22>0,B22*Assumptions!E91,0) -> 0 | C23: =IF(C22>0,C22*Assumptions!F91,0) -> 120.64509 | D23: =IF(D22>0,D22*Assumptions!G91,0) -> 598.06446 | E23: =IF(E22>0,E22*Assumptions!H91,0) -> 1215.8157 | F23: =IF(F22>0,F22*Assumptions!I91,0) -> 2154.1671
A24: NET INCOME (LOSS) | B24: =B22-B23 -> -451.6632 | C24: =C22-C23 -> 361.93527 | D24: =D22-D23 -> 1794.1934 | E24: =E22-E23 -> 3647.447 | F24: =F22-F23 -> 6462.5014

Sheet Depreciation Schedule
A1: Depreciation Schedule
A3: Particulars | B3: (in Rs Lakhs)
B4: FY27E | C4: FY28E | D4: FY29E | E4: FY30E | F4: FY31E
A5: Opening | B5: =Assumptions!D29 -> 2955 | C5: =B9 -> 4729.5 | D5: =C9 -> 6956.55 | E5: =D9 -> 9590.895 | F5: =E9 -> 12591.805
A6: New Capex | B6: =Assumptions!E87 -> 2300 | C6: =Assumptions!F87 -> 3000 | D6: =Assumptions!G87 -> 3700 | E6: =Assumptions!H87 -> 4400 | F6: =Assumptions!I87 -> 5100
A7: Total | B7: =SUM(B5:B6) -> 5255 | C7: =SUM(C5:C6) -> 7729.5 | D7: =SUM(D5:D6) -> 10656.55 | E7: =SUM(E5:E6) -> 13990.895 | F7: =SUM(F5:F6) -> 17691.805
A8: Depreciation | B8: =Assumptions!E88*B7 -> 525.5 | C8: =Assumptions!F88*C7 -> 772.95 | D8: =Assumptions!G88*D7 -> 1065.655 | E8: =Assumptions!H88*E7 -> 1399.0895 | F8: =Assumptions!I88*F7 -> 1769.1806
A9: Closing | B9: =B5+B6-B8 -> 4729.5 | C9: =C5+C6-C8 -> 6956.55 | D9: =D5+D6-D8 -> 9590.895 | E9: =E5+E6-E8 -> 12591.805 | F9: =F5+F6-F8 -> 15922.625

Sheet Loan Schedule
A1: WC Loan Schedule
A3: Particulars | B3: (in Rs Lakhs)
B4: FY27E | C4: FY28E | D4: FY29E | E4: FY30E | F4: FY31E
A5: Opening | B5: =Assumptions!D33 -> 1100 | C5: =B7 -> 1300 | D5: =C7 -> 1500 | E5: =D7 -> 1700 | F5: =E7 -> 1900
A6: New debt | B6: =B7-B5 -> 200 | C6: =C7-C5 -> 200 | D6: =D7-D5 -> 200 | E6: =E7-E5 -> 200 | F6: =F7-F5 -> 200
A7: Closing | B7: =Assumptions!E89 -> 1300 | C7: =Assumptions!F89 -> 1500 | D7: =Assumptions!G89 -> 1700 | E7: =Assumptions!H89 -> 1900 | F7: =Assumptions!I89 -> 2100
A8: Average | B8: =(B5+B7)/2 -> 1200 | C8: =(C5+C7)/2 -> 1400 | D8: =(D5+D7)/2 -> 1600 | E8: =(E5+E7)/2 -> 1800 | F8: =(F5+F7)/2 -> 2000
A9: Interest | B9: =B8*Assumptions!E90 -> 180 | C9: =C8*Assumptions!F90 -> 210 | D9: =D8*Assumptions!G90 -> 240 | E9: =E8*Assumptions!H90 -> 270 | F9: =F8*Assumptions!I90 -> 300

Sheet Working Capital Schedule
A1: Working Capital Schedule
A3: Particulars | B3: (in Rs Lakhs)
B4: FY27E | C4: FY28E | D4: FY29E | E4: FY30E | F4: FY31E
A5: Accounts Receivables | B5: ='Income Statement'!B8*Assumptions!E92 -> 634.592 | C5: ='Income Statement'!C8*Assumptions!F92 -> 1046.8074 | D5: ='Income Statement'!D8*Assumptions!G92 -> 1607.7882 | E5: ='Income Statement'!E8*Assumptions!H92 -> 2292.0534 | F5: ='Income Statement'!F8*Assumptions!I92 -> 3142.8968
A6: Inventory | B6: ='Income Statement'!B8*Assumptions!E94 -> 412.4848 | C6: ='Income Statement'!C8*Assumptions!F94 -> 628.08444 | D6: ='Income Statement'!D8*Assumptions!G94 -> 884.28351 | E6: ='Income Statement'!E8*Assumptions!H94 -> 1146.0267 | F6: ='Income Statement'!F8*Assumptions!I94 -> 1414.3036
A7: Accounts Payables | B7: ='Income Statement'!B8*Assumptions!E93 -> 444.2144 | C7: ='Income Statement'!C8*Assumptions!F93 -> 732.76518 | D7: ='Income Statement'!D8*Assumptions!G93 -> 1125.4517 | E7: ='Income Statement'!E8*Assumptions!H93 -> 1604.4374 | F7: ='Income Statement'!F8*Assumptions!I93 -> 2200.0278
A8: Accrued Payroll | B8: ='Balance Sheet'!B14 -> 253.8368 | C8: ='Balance Sheet'!C14 -> 418.72296 | D8: ='Balance Sheet'!D14 -> 643.11528 | E8: ='Balance Sheet'!E14 -> 916.82136 | F8: ='Balance Sheet'!F14 -> 1257.1587
A9: Working Capital | B9: =B5+B6-B7-B8 -> 349.0256 | C9: =C5+C6-C7-C8 -> 523.4037 | D9: =D5+D6-D7-D8 -> 723.50469 | E9: =E5+E6-E7-E8 -> 916.82136 | F9: =F5+F6-F7-F8 -> 1100.0139
A10: Changes | B10: =Assumptions!D26+Assumptions!D27-Assumptions!D31-'Working Capital Schedule'!B9-Assumptions!D32 -> -94.0256 | C10: =B9-C9 -> -174.3781 | D10: =C9-D9 -> -200.10099 | E10: =D9-E9 -> -193.31667 | F10: =E9-F9 -> -183.19252

Sheet Balance Sheet
A1: BALANCE SHEET — Task 2 (₹ Lakhs, year-end)
A2: ₹ in Lakhs unless noted | B2: FY27E | C2: FY28E | D2: FY29E | E2: FY30E | F2: FY31E
A4: ASSETS
A5: Cash & Equivalents | B5: ='Cash Flow'!B15 -> 13246.811 | C5: ='Cash Flow'!C15 -> 11407.318 | D5: ='Cash Flow'!D15 -> 10567.066 | E5: ='Cash Flow'!E15 -> 11220.286 | F5: ='Cash Flow'!F15 -> 14368.775
A6: Accounts Receivable | B6: ='Working Capital Schedule'!B5 -> 634.592 | C6: ='Working Capital Schedule'!C5 -> 1046.8074 | D6: ='Working Capital Schedule'!D5 -> 1607.7882 | E6: ='Working Capital Schedule'!E5 -> 2292.0534 | F6: ='Working Capital Schedule'!F5 -> 3142.8968
A7: Prepaid Expenses / Inventory | B7: ='Working Capital Schedule'!B6 -> 412.4848 | C7: ='Working Capital Schedule'!C6 -> 628.08444 | D7: ='Working Capital Schedule'!D6 -> 884.28351 | E7: ='Working Capital Schedule'!E6 -> 1146.0267 | F7: ='Working Capital Schedule'!F6 -> 1414.3036
A8: TOTAL CURRENT ASSETS | B8: =SUM(B5:B7) -> 14293.888 | C8: =SUM(C5:C7) -> 13082.21 | D8: =SUM(D5:D7) -> 13059.137 | E8: =SUM(E5:E7) -> 14658.366 | F8: =SUM(F5:F7) -> 18925.975
A9: PP&E & Warehouse Structures (net) | B9: ='Depreciation Schedule'!B9 -> 4729.5 | C9: ='Depreciation Schedule'!C9 -> 6956.55 | D9: ='Depreciation Schedule'!D9 -> 9590.895 | E9: ='Depreciation Schedule'!E9 -> 12591.805 | F9: ='Depreciation Schedule'!F9 -> 15922.625
A10: TOTAL ASSETS | B10: =SUM(B8:B9) -> 19023.388 | C10: =SUM(C8:C9) -> 20038.76 | D10: =SUM(D8:D9) -> 22650.032 | E10: =SUM(E8:E9) -> 27250.171 | F10: =SUM(F8:F9) -> 34848.6
A12: LIABILITIES
A13: Accounts Payable | B13: ='Working Capital Schedule'!B7 -> 444.2144 | C13: ='Working Capital Schedule'!C7 -> 732.76518 | D13: ='Working Capital Schedule'!D7 -> 1125.4517 | E13: ='Working Capital Schedule'!E7 -> 1604.4374 | F13: ='Working Capital Schedule'!F7 -> 2200.0278
A14: Accured Payroll | B14: =Assumptions!E95*'Income Statement'!B8 -> 253.8368 | C14: =Assumptions!F95*'Income Statement'!C8 -> 418.72296 | D14: =Assumptions!G95*'Income Statement'!D8 -> 643.11528 | E14: =Assumptions!H95*'Income Statement'!E8 -> 916.82136 | F14: =Assumptions!I95*'Income Statement'!F8 -> 1257.1587
A15: Short-term Working Capital Loan | B15: ='Loan Schedule'!B7 -> 1300 | C15: ='Loan Schedule'!C7 -> 1500 | D15: ='Loan Schedule'!D7 -> 1700 | E15: ='Loan Schedule'!E7 -> 1900 | F15: ='Loan Schedule'!F7 -> 2100
A16: TOTAL LIABILITIES | B16: =SUM(B13:B15) -> 1998.0512 | C16: =SUM(C13:C15) -> 2651.4881 | D16: =SUM(D13:D15) -> 3468.567 | E16: =SUM(E13:E15) -> 4421.2587 | F16: =SUM(F13:F15) -> 5557.1865
A18: EQUITY
A19: Paid-in Capital | B19: =Assumptions!D35+Assumptions!E96*100 -> 19350 | C19: =B19 -> 19350 | D19: =C19 -> 19350 | E19: =D19 -> 19350 | F19: =E19 -> 19350
A20: Accumulated Deficit | B20: =Assumptions!D36+'Income Statement'!B24 -> -2324.6632 | C20: =B20+'Income Statement'!C24 -> -1962.7279 | D20: =C20+'Income Statement'!D24 -> -168.53454 | E20: =D20+'Income Statement'!E24 -> 3478.9125 | F20: =E20+'Income Statement'!F24 -> 9941.4139
A21: TOTAL EQUITY | B21: =SUM(B19:B20) -> 17025.337 | C21: =SUM(C19:C20) -> 17387.272 | D21: =SUM(D19:D20) -> 19181.465 | E21: =SUM(E19:E20) -> 22828.912 | F21: =SUM(F19:F20) -> 29291.414
A22: TOTAL LIABILITIES + EQUITY | B22: =B21+B16 -> 19023.388 | C22: =C21+C16 -> 20038.76 | D22: =D21+D16 -> 22650.032 | E22: =E21+E16 -> 27250.171 | F22: =F21+F16 -> 34848.6
A23: Check (Assets - Liab - Equity = 0) | B23: =B10-B22 -> 0 | C23: =C10-C22 -> 0 | D23: =D10-D22 -> 0 | E23: =E10-E22 -> 0 | F23: =F10-F22 -> 0

Sheet Cash Flow
A1: CASH FLOW STATEMENT (₹ Lakhs)
A2: ₹ in Lakhs unless noted | B2: FY27E | C2: FY28E | D2: FY29E | E2: FY30E | F2: FY31E
A4: Net Income | B4: ='Income Statement'!B24 -> -451.6632 | C4: ='Income Statement'!C24 -> 361.93527 | D4: ='Income Statement'!D24 -> 1794.1934 | E4: ='Income Statement'!E24 -> 3647.447 | F4: ='Income Statement'!F24 -> 6462.5014
A5: D&A add-back | B5: ='Depreciation Schedule'!B8 -> 525.5 | C5: ='Depreciation Schedule'!C8 -> 772.95 | D5: ='Depreciation Schedule'!D8 -> 1065.655 | E5: ='Depreciation Schedule'!E8 -> 1399.0895 | F5: ='Depreciation Schedule'!F8 -> 1769.1806
A6: Change in Net Working Capital | B6: ='Working Capital Schedule'!B10 -> -94.0256 | C6: ='Working Capital Schedule'!C10 -> -174.3781 | D6: ='Working Capital Schedule'!D10 -> -200.10099 | E6: ='Working Capital Schedule'!E10 -> -193.31667 | F6: ='Working Capital Schedule'!F10 -> -183.19252
A7: CASH FLOW FROM OPERATIONS | B7: =SUM(B4:B6) -> -20.1888 | C7: =SUM(C4:C6) -> 960.50717 | D7: =SUM(D4:D6) -> 2659.7474 | E7: =SUM(E4:E6) -> 4853.2198 | F7: =SUM(F4:F6) -> 8048.4895
A8: Capex | B8: =-Assumptions!E87 -> -2300 | C8: =-Assumptions!F87 -> -3000 | D8: =-Assumptions!G87 -> -3700 | E8: =-Assumptions!H87 -> -4400 | F8: =-Assumptions!I87 -> -5100
A9: CASH FLOW FROM INVESTING | B9: =B8 -> -2300 | C9: =C8 -> -3000 | D9: =D8 -> -3700 | E9: =E8 -> -4400 | F9: =F8 -> -5100
A10: Equity Raised | B10: =14000 -> 14000
A11: Debt Drawn (net) | B11: ='Loan Schedule'!B6 -> 200 | C11: ='Loan Schedule'!C6 -> 200 | D11: ='Loan Schedule'!D6 -> 200 | E11: ='Loan Schedule'!E6 -> 200 | F11: ='Loan Schedule'!F6 -> 200
A12: CASH FLOW FROM FINANCING | B12: =SUM(B10:B11) -> 14200 | C12: =SUM(C10:C11) -> 200 | D12: =SUM(D10:D11) -> 200 | E12: =SUM(E10:E11) -> 200 | F12: =SUM(F10:F11) -> 200
A13: NET CHANGE IN CASH | B13: =B7+B9+B12 -> 11879.811 | C13: =C7+C9+C12 -> -1839.4928 | D13: =D7+D9+D12 -> -840.2526 | E13: =E7+E9+E12 -> 653.21985 | F13: =F7+F9+F12 -> 3148.4895
A14: Opening Cash | B14: =Assumptions!D25 -> 1367 | C14: =B15 -> 13246.811 | D14: =C15 -> 11407.318 | E14: =D15 -> 10567.066 | F14: =E15 -> 11220.286
A15: Closing Cash | B15: =B13+B14 -> 13246.811 | C15: =C13+C14 -> 11407.318 | D15: =D13+D14 -> 10567.066 | E15: =E13+E14 -> 11220.286 | F15: =F13+F14 -> 14368.775
A17: FCFF
A18: NOPAT | B18: ='Income Statement'!B20-MAX('Income Statement'!B20*Assumptions!E91,0) -> -271.6632 | C18: ='Income Statement'!C20-MAX('Income Statement'!C20*Assumptions!F91,0) -> 519.43527 | D18: ='Income Statement'!D20-MAX('Income Statement'!D20*Assumptions!G91,0) -> 1974.1934 | E18: ='Income Statement'!E20-MAX('Income Statement'!E20*Assumptions!H91,0) -> 3849.947 | F18: ='Income Statement'!F20-MAX('Income Statement'!F20*Assumptions!I91,0) -> 6687.5014
A19: (+)Depreciation | B19: =B5 -> 525.5 | C19: =C5 -> 772.95 | D19: =D5 -> 1065.655 | E19: =E5 -> 1399.0895 | F19: =F5 -> 1769.1806
A20: (-) Capex | B20: =B8 -> -2300 | C20: =C8 -> -3000 | D20: =D8 -> -3700 | E20: =E8 -> -4400 | F20: =F8 -> -5100
A21: (-) Changes in working capital | B21: =B6 -> -94.0256 | C21: =C6 -> -174.3781 | D21: =D6 -> -200.10099 | E21: =E6 -> -193.31667 | F21: =F6 -> -183.19252
A22: Free Cash Flow to Firm | B22: =SUM(B18:B21) -> -2140.1888 | C22: =SUM(C18:C21) -> -1881.9928 | D22: =SUM(D18:D21) -> -860.2526 | E22: =SUM(E18:E21) -> 655.71985 | F22: =SUM(F18:F21) -> 3173.4895

Sheet WACC
A1: Weighted Average Cost of Capital
A3: Cost of Debt | D3: WACC (Pre Series B)
A4: Particulars | B4: % | D4: Particulars | E4: Amount | F4: Weight
A5: Interest rate | B5: 15 | D5: Total Equity | E5: =Assumptions!D37 -> 3477 | F5: =E5/SUM(E5:E6) -> 0.7596679
A6: Tax | B6: 25 | D6: Total Debt | E6: =Assumptions!D33 -> 1100 | F6: =E6/SUM(E5:E6) -> 0.2403321
A7: After tax COD | B7: =B5%*(1-B6%) -> 0.1125 | D7: =A7 -> After tax COD | E7: =B7 -> 0.1125
D8: =A15 -> Cost of Equity | E8: =B15 -> 0.1590864
A9: Cost of Equity | D9: WACC | E9: =(E7*F6)+(E8*F5) -> 0.14789019
A10: Particulars | B10: %
A11: Risk Free Rate | B11: 6.85
A12: Beta (number) | B12: 0.442
A13: Equity Risk Premium | B13: 6.92
A14: Illiquidity premium | B14: 6
A15: Cost of Equity | B15: =B11%+(B12*B13%)+B14% -> 0.1590864
A17: (Refer Cost of Capital analysis document)

Sheet Valuation
A1: VALUATION
A3: A. DISCOUNTED CASH FLOW (DCF)
A4: Note: pull Free Cash Flow for each year from your Cash Flow Statement tab.
B5: 1 | C5: 2 | D5: 3 | E5: 4 | F5: 5
A6: Particulars | B6: FY27E | C6: FY28E | D6: FY29E | E6: FY30E | F6: FY31E
A7: Free Cash Flow (₹ L) | B7: ='Cash Flow'!B22 -> -2140.1888 | C7: ='Cash Flow'!C22 -> -1881.9928 | D7: ='Cash Flow'!D22 -> -860.2526 | E7: ='Cash Flow'!E22 -> 655.71985 | F7: ='Cash Flow'!F22 -> 3173.4895
A8: Discount Factor | B8: =1/(1+WACC!$E$9)^B5 -> 0.87116347 | C8: =1/(1+WACC!$E$9)^C5 -> 0.75892579 | D8: =1/(1+WACC!$E$9)^D5 -> 0.66114842 | E8: =1/(1+WACC!$E$9)^E5 -> 0.57596835 | F8: =1/(1+WACC!$E$9)^F5 -> 0.50176258
A9: Present Value of FCF (₹ L) | B9: =B7*B8 -> -1864.4543 | C9: =C7*C8 -> -1428.2929 | D9: =D7*D8 -> -568.75464 | E9: =E7*E8 -> 377.67388 | F9: =F7*F8 -> 1592.3383
A11: Discount Rate / WACC | B11: =WACC!E9 -> 0.14789019
A12: Terminal Growth Rate | B12: 0.06
A13: Terminal Value (₹ L) | B13: =F7*(1+B12)/(B11-B12) -> 38273.881
A14: PV of Terminal Value (₹ L) | B14: =B13*F8 -> 19204.402
A15: Sum of PV of FCF (₹ L) | B15: =SUM(B9:F9) -> -1891.4897
A16: Enterprise Value (₹ L) | B16: =SUM(B14:B15) -> 17312.912
A17: Enterprise Value (₹ Cr) | B17: =B16/100 -> 173.12912
A18: Equity Value (in ₹Cr) | B18: =(B16+Assumptions!D25-Assumptions!D33)/100 -> 175.79912
A20: B. COMPARABLE COMPANY / PRECEDENT TRANSACTION ANALYSIS
A21: Comparable | B21: Metric Used | C21: Multiple | D21: Multiple considered | E21: Annapurna Metric (₹ Cr) | F21: Implied Valuation (₹ Cr) | G21: PV of IV (₹ Cr)
A22: Arya.ag | B22: EV/Revenue | C22: 6x to 7.5x | D22: 7.5 | E22: ='Income Statement'!F8/100 -> 314.28968 | F22: =D22*E22 -> 2357.1726 | G22: =F22*F8 -> 1182.741
A23: DeHaat | B23: EV/Revenue | C23: 2.0x to 2.3x | D23: 2 | E23: =E22 -> 314.28968 | F23: =D23*E23 -> 628.57936 | G23: =F23*F8 -> 315.3976
A24: (Refer Cost of capital and Comps Report)
A26: Valuation Range (₹ Cr) | B26: =CONCATENATE(ROUND(MIN(B18,G22,G23),0)," - ",ROUND(MAX(B18,G22,G23),0)) -> 176 - 1183
A27: Average of all (₹ Cr) | B27: =AVERAGE(B18,G22,G23) -> 557.97925
A28: Pre-Money Valuation (₹ Cr) | B28: 560
A29: Post-Money Valuation (₹ Cr) | B29: =B28+('Cap Table'!B24/10000000) -> 700
A31: C. SENSITIVITY ANALYSIS
A33: PARTICULARS | C33: DISCOUNT RATE (WACC)
B34: =B18 -> 175.79912 | C34: =D34-1% -> 0.128 | D34: =E34-1% -> 0.138 | E34: 0.148 | F34: =E34+1% -> 0.158 | G34: =F34+1% -> 0.168
A35: TERMINAL GROWTH RATE | B35: 0.04 | C35: 171.94053 | D35: 152.73794 | E35: 137.09138 | F35: 124.09678 | G35: 113.13259
B36: 0.05 | C36: 198.10833 | D36: 173.75001 | E36: 154.36277 | F36: 138.56577 | G36: 125.44622
B37: 0.06 | C37: 231.97254 | D37: 200.14979 | E37: 175.55949 | F37: 155.98761 | G37: 140.04016
B38: 0.07 | C38: 277.51406 | D38: 234.31421 | E38: 202.19125 | F38: 177.36896 | G38: 157.61244
B39: 0.08 | C39: 342.03121 | D39: 280.25947 | E39: 236.65589 | F39: 204.23271 | G39: 179.17844
A41: D. SCENARIO ANALYSIS
A43: Choose Case | B43: Base | C43: =IF(B43="Base",1,IF(B43="Bull",2,IF(B43="Bear",3,IF(B43="(select)",1)))) -> 1 | I43: 1
A44: PV FCFF (in Rs Lakhs) | B44: =B14 -> 19204.402
A45: PV Terminal Value (in Rs Lakhs) | B45: =B15 -> -1891.4897
A46: Enterprise Value (in Rs Lakhs) | B46: =B16 -> 17312.912
A47: Debt (in Rs Lakhs) | B47: =Assumptions!D33 -> 1100
A48: Cash (in Rs Lakhs) | B48: =Assumptions!D25 -> 1367
...

Sheet Cap Table
A1: CAP TABLE pro-forma post-Series B
A3: Reference the current cap table on the Assumptions tab for pre-Series B ownership.
A5: Shareholder | B5: Pre-Series B % | C5: Pre-Series B Shares | D5: New Shares (Series B + ESOP top-up) | E5: Post-Series B Shares | F5: Post-Series B %
A6: Priya Deshmukh (CEO) | B6: =Assumptions!B110 -> 0.23 | C6: 2300000 | E6: =C6 -> 2300000 | F6: =E6/$E$16 -> 0.17864078
A7: Rohan Iyer (CTO) | B7: =Assumptions!B111 -> 0.19 | C7: 1900000 | E7: =C7 -> 1900000 | F7: =E7/$E$16 -> 0.14757282
A8: Suresh Patil (COO) | B8: =Assumptions!B112 -> 0.13 | C8: 1300000 | E8: =C8 -> 1300000 | F8: =E8/$E$16 -> 0.10097087
A9: ESOP Pool | B9: =Assumptions!B113 -> 0.1 | C9: 1000000 | E9: =C9 -> 1000000 | F9: =E9/$E$16 -> 0.077669903
A10: Angel Syndicate (Pre-Seed) | B10: =Assumptions!B114 -> 0.045 | C10: 450000 | E10: =C10 -> 450000 | F10: =E10/$E$16 -> 0.034951456
A11: AgriTech Fund (Seed) | B11: =Assumptions!B115 -> 0.125 | C11: 1250000 | E11: =C11 -> 1250000 | F11: =E11/$E$16 -> 0.097087379
A12: Growth Fund (Series A) | B12: =Assumptions!B116 -> 0.15 | C12: 1500000 | E12: =C12 -> 1500000 | F12: =E12/$E$16 -> 0.11650485
A13: AgriTech Fund (Series A follow-on) | B13: =Assumptions!B117 -> 0.03 | C13: 300000 | E13: =C13 -> 300000 | F13: =E13/$E$16 -> 0.023300971
A14: ESOP Top-Up (new) | D14: =C16*3% -> 300000 | E14: =C16*3% -> 300000 | F14: =E14/$E$16 -> 0.023300971
A15: Series B Investor (new) | D15: =B25 -> 2575000 | E15: =B25 -> 2575000 | F15: =E15/$E$16 -> 0.2
A16: Total | B16: =SUM(B6:B15) -> 1 | C16: =SUM(C6:C15) -> 10000000 | E16: =SUM(E6:E15) -> 12875000 | F16: =SUM(F6:F15) -> 1
A19: Share value and New equity workings
A20: Particulars | B20: Amount (in Rs)
A21: Pre Money Valuation | B21: =Valuation!B28*10000000 -> 5600000000
A22: Current shares (post ESOP Topup) | B22: =C16+E14 -> 10300000
A23: Share price | B23: =B21/B22 -> 543.68932
A24: New investment | B24: 1400000000
A25: No of Shares | B25: =B24/B23 -> 2575000

Sheet TAM SAM SOM
A1: TAM / SAM / SOM independent rebuild
A3: Given figures (see Assumptions tab): TAM ₹8,40,000 Cr · SAM ₹2,40,000 Cr · SOM ₹6,000 Cr/yr (aspiration)
A5: Metric | B5: Your Methodology / Assumptions | C5: Your Value (₹ Cr)
A6: TAM (bottom-up) | B6: FY26 actual production (foodgrain 376.56 MT + oilseeds 43.06 MT, per Ministry of Agriculture 3rd Advance Estimates) x blended MSP-based price/tonne (cereals Rs21,000/t, pulses Rs65,000/t, oilseeds Rs55,000/t) = Rs11,55,207 Cr gross production value. Applied a 68% marketable-surplus factor (share of output actually sold rather than retained for self-consumption/seed/feed, which can never be warehouse-financed) to arrive at the addressable value. | C6: 785541
A7: TAM (top-down cross-check) | B7: India Agri GVA FY26 (Rs52,08,800 Cr) x ~54% crop share x ~45% storable-crop (cereals/pulses/oilseeds) share of crop GVA (excl. horticulture, cotton, sugarcane, plantation crops) = ~Rs12,66,000 Cr gross, x 68% marketable-surplus factor. | C7: 860000
A8: SAM | B8: Case defines SAM by bank/NBFC partner geographic coverage. Annapurna targets 16+ states post-Series B; India's top 16 agri-producing states (UP, Punjab, Haryana, MP, Maharashtra, Rajasthan, Karnataka, AP, Telangana, Bihar, WB, Gujarat, Chhattisgarh, Odisha, TN, Assam) account for ~80% of national storable-crop marketable surplus. SAM = 80% x independent TAM (Rs8,40,000 Cr average of bottom-up/top-down). This is ~2.8x the case's stated SAM (Rs2,40,000 Cr / 28.6%), since owning mini-warehouses removes the binary "does a warehouse exist here" constraint - see critique below. | C8: 672000
A9: SOM (5-year) | B9: Taken directly from our own Task 1 driver-based forecast (not a separate top-down guess): FY31E annual loan disbursement volume = Rs1,979 Cr, i.e. ~0.29% of independent SAM. The case's Rs6,000 Cr/yr figure is a longer-horizon aspiration beyond this model's 5-year window (~0.89% of independent SAM), representing further share-of-SAM capture after FY31. | C9: 1979
A10: (Refer TAM SAM SOM Analysis report)
A12: Critique: does owning mini-warehouses genuinely remove the "existing warehouse density" constraint on SAM,
A13: or does it just trade one constraint (partner availability) for another (Annapurna's own build-out pace/capital)?
